Workbook

Sheet 总表
A1: 机器编号 | B1: 线路 | C1: 点位名称 | D1: 所属督导 | E1: 运维人 | F1: 上周运维频率（次） | G1: 本周运维频率（次） | H1: 上周期总杯数 | I1: 本周期总杯数 | J1: 差异% | K1: 总金额 | L1: 测试杯 | M1: 停机时长 | N1: 停机原因备注 | O1: 投诉总量 | P1: 投诉率 | Q1: 缺料故障情况 | R1: 客户投诉 | S1: 异常事件 | T1: 事件备注
A2: 12248 | B2: 市区 | C2: 江门市中心医院外科4楼手术室 | D2: 李小兰 | F2: 2 | G2: =VLOOKUP(A2,运维频率!A2:B299,2,FALSE) -> 2 | H2: =VLOOKUP(A2,上周期销售数据表!$A2:$O200,15,FALSE) -> 25 | I2: =VLOOKUP(A2,本周期销售数据表!$A2:$O200,15,FALSE) -> 28 | J2: =(I2-H2)/H2*100% -> 0.12 | K2: =VLOOKUP(A2,本周期销售数据表!$A2:$L200,10,FALSE) -> 279.8 | L2: =VLOOKUP(A2,本周期销售数据表!$A2:$L200,7,FALSE) -> 2 | AC2: =H2+20 -> 45 | AD2: =H2-20 -> 5
A3: 18890 | B3: 市区 | C3: 江门市中心内科 | D3: 李小兰 | F3: 3 | G3: =VLOOKUP(A3,运维频率!A2:B299,2,FALSE) -> 3 | H3: =VLOOKUP(A3,上周期销售数据表!$A2:$O200,15,FALSE) -> 63 | I3: =VLOOKUP(A3,本周期销售数据表!$A2:$O200,15,FALSE) -> 57 | J3: =(I3-H3)/H3*100% -> -0.095238095 | K3: =VLOOKUP(A3,本周期销售数据表!$A2:$L200,10,FALSE) -> 565.64 | L3: =VLOOKUP(A3,本周期销售数据表!$A2:$L200,7,FALSE) -> 1 | AC3: =H3+20 -> 83 | AD3: =H3-20 -> 43
A4: 51776 | B4: 市区 | C4: 江门市中心医院门诊大堂 | D4: 李小兰 | F4: 5 | G4: =VLOOKUP(A4,运维频率!A2:B299,2,FALSE) -> 4 | H4: =VLOOKUP(A4,上周期销售数据表!$A2:$O200,15,FALSE) -> 343 | I4: =VLOOKUP(A4,本周期销售数据表!$A2:$O200,15,FALSE) -> 408 | J4: =(I4-H4)/H4*100% -> 0.18950437 | K4: =VLOOKUP(A4,本周期销售数据表!$A2:$L200,10,FALSE) -> 4694.74 | L4: =VLOOKUP(A4,本周期销售数据表!$A2:$L200,7,FALSE) -> 3 | AC4: =H4+20 -> 363 | AD4: =H4-20 -> 323
A5: 52935 | B5: 市区 | C5: 江门市中心医院门诊4楼 | D5: 李小兰 | F5: 2 | G5: =VLOOKUP(A5,运维频率!A2:B299,2,FALSE) -> 2 | H5: =VLOOKUP(A5,上周期销售数据表!$A2:$O200,15,FALSE) -> 49 | I5: =VLOOKUP(A5,本周期销售数据表!$A2:$O200,15,FALSE) -> 33 | J5: =(I5-H5)/H5*100% -> -0.32653061 | K5: =VLOOKUP(A5,本周期销售数据表!$A2:$L200,10,FALSE) -> 323.9 | L5: =VLOOKUP(A5,本周期销售数据表!$A2:$L200,7,FALSE) -> 2 | AC5: =H5+20 -> 69 | AD5: =H5-20 -> 29
A6: 35948 | B6: 市区 | C6: 江门市中心医院外科 | D6: 李小兰 | F6: 4 | G6: =VLOOKUP(A6,运维频率!A2:B299,2,FALSE) -> 3 | H6: =VLOOKUP(A6,上周期销售数据表!$A2:$O200,15,FALSE) -> 96 | I6: =VLOOKUP(A6,本周期销售数据表!$A2:$O200,15,FALSE) -> 83 | J6: =(I6-H6)/H6*100% -> -0.13541667 | K6: =VLOOKUP(A6,本周期销售数据表!$A2:$L200,10,FALSE) -> 922.5 | L6: =VLOOKUP(A6,本周期销售数据表!$A2:$L200,7,FALSE) -> 2 | AC6: =H6+20 -> 116 | AD6: =H6-20 -> 76
A7: 74081 | B7: 开平 | C7: 开平市赤坎服务区南区 | D7: 张礼初 | F7: 2 | G7: =VLOOKUP(A7,运维频率!A2:B299,2,FALSE) -> 1 | H7: =VLOOKUP(A7,上周期销售数据表!$A2:$O200,15,FALSE) -> 192 | I7: =VLOOKUP(A7,本周期销售数据表!$A2:$O200,15,FALSE) -> 50 | J7: =(I7-H7)/H7*100% -> -0.73958333 | K7: =VLOOKUP(A7,本周期销售数据表!$A2:$L200,10,FALSE) -> 812.4 | L7: =VLOOKUP(A7,本周期销售数据表!$A2:$L200,7,FALSE) -> 0 | AC7: =H7+20 -> 212 | AD7: =H7-20 -> 172
A8: 19712 | B8: 市区 | C8: 江门市第二人民医院门诊楼 | D8: 李小兰 | F8: 0 | G8: =VLOOKUP(A8,运维频率!A2:B299,2,FALSE) -> 0 | H8: =VLOOKUP(A8,上周期销售数据表!$A2:$O200,15,FALSE) -> #N/A | I8: =VLOOKUP(A8,本周期销售数据表!$A2:$O200,15,FALSE) -> #N/A | J8: =(I8-H8)/H8*100% -> #N/A | K8: =VLOOKUP(A8,本周期销售数据表!$A2:$L200,10,FALSE) -> #N/A | L8: =VLOOKUP(A8,本周期销售数据表!$A2:$L200,7,FALSE) -> #N/A | AC8: =H8+20 -> #N/A | AD8: =H8-20 -> #N/A
A9: 19662 | B9: 市区 | C9: 江门市新会中医院2号楼大堂 | D9: 李小兰 | F9: 2 | G9: =VLOOKUP(A9,运维频率!A2:B299,2,FALSE) -> 1 | H9: =VLOOKUP(A9,上周期销售数据表!$A2:$O200,15,FALSE) -> 22 | I9: =VLOOKUP(A9,本周期销售数据表!$A2:$O200,15,FALSE) -> 5 | J9: =(I9-H9)/H9*100% -> -0.77272727 | K9: =VLOOKUP(A9,本周期销售数据表!$A2:$L200,10,FALSE) -> 30.4 | L9: =VLOOKUP(A9,本周期销售数据表!$A2:$L200,7,FALSE) -> 3 | AC9: =H9+20 -> 42 | AD9: =H9-20 -> 2
A10: 68720 | B10: 市区 | C10: 新会人民医院住院部大堂 | D10: 李小兰 | F10: 2 | G10: =VLOOKUP(A10,运维频率!A2:B299,2,FALSE) -> 2 | H10: =VLOOKUP(A10,上周期销售数据表!$A2:$O200,15,FALSE) -> 30 | I10: =VLOOKUP(A10,本周期销售数据表!$A2:$O200,15,FALSE) -> 34 | J10: =(I10-H10)/H10*100% -> 0.13333333 | K10: =VLOOKUP(A10,本周期销售数据表!$A2:$L200,10,FALSE) -> 376.4 | L10: =VLOOKUP(A10,本周期销售数据表!$A2:$L200,7,FALSE) -> 2 | AC10: =H10+20 -> 50 | AD10: =H10-20 -> 10
A11: 68721 | B11: 市区 | C11: 新会人民医院门诊 | D11: 李小兰 | F11: 1 | G11: =VLOOKUP(A11,运维频率!A2:B299,2,FALSE) -> 3 | H11: =VLOOKUP(A11,上周期销售数据表!$A2:$O200,15,FALSE) -> 33 | I11: =VLOOKUP(A11,本周期销售数据表!$A2:$O200,15,FALSE) -> 24 | J11: =(I11-H11)/H11*100% -> -0.27272727 | K11: =VLOOKUP(A11,本周期销售数据表!$A2:$L200,10,FALSE) -> 273.3 | L11: =VLOOKUP(A11,本周期销售数据表!$A2:$L200,7,FALSE) -> 4 | AC11: =H11+20 -> 53 | AD11: =H11-20 -> 13
A12: 13441 | B12: 市区 | C12: 江门市购书中心 | D12: 李小兰 | F12: 1 | G12: =VLOOKUP(A12,运维频率!A2:B299,2,FALSE) -> 1 | H12: =VLOOKUP(A12,上周期销售数据表!$A2:$O200,15,FALSE) -> 12 | I12: =VLOOKUP(A12,本周期销售数据表!$A2:$O200,15,FALSE) -> 5 | J12: =(I12-H12)/H12*100% -> -0.58333333 | K12: =VLOOKUP(A12,本周期销售数据表!$A2:$L200,10,FALSE) -> 54 | L12: =VLOOKUP(A12,本周期销售数据表!$A2:$L200,7,FALSE) -> 1 | AC12: =H12+20 -> 32 | AD12: =H12-20 -> -8
A13: 26039 | B13: 市区 | C13: 广州市孙逸仙花都区急诊 | D13: 黄梓烽 | F13: 1 | G13: =VLOOKUP(A13,运维频率!A2:B299,2,FALSE) -> 2 | H13: =VLOOKUP(A13,上周期销售数据表!$A2:$O200,15,FALSE) -> 11 | I13: =VLOOKUP(A13,本周期销售数据表!$A2:$O200,15,FALSE) -> 10 | J13: =(I13-H13)/H13*100% -> -0.090909091 | K13: =VLOOKUP(A13,本周期销售数据表!$A2:$L200,10,FALSE) -> 110 | L13: =VLOOKUP(A13,本周期销售数据表!$A2:$L200,7,FALSE) -> 1 | AC13: =H13+20 -> 31 | AD13: =H13-20 -> -9
A14: 22520 | B14: 市区 | C14: 江门市爱尔新希望8楼 | D14: 李小兰 | F14: 0 | G14: =VLOOKUP(A14,运维频率!A2:B299,2,FALSE) -> 0 | H14: =VLOOKUP(A14,上周期销售数据表!$A2:$O200,15,FALSE) -> #N/A | I14: =VLOOKUP(A14,本周期销售数据表!$A2:$O200,15,FALSE) -> #N/A | J14: =(I14-H14)/H14*100% -> #N/A | K14: =VLOOKUP(A14,本周期销售数据表!$A2:$L200,10,FALSE) -> #N/A | L14: =VLOOKUP(A14,本周期销售数据表!$A2:$L200,7,FALSE) -> #N/A | AC14: =H14+20 -> #N/A | AD14: =H14-20 -> #N/A
A15: 23399 | B15: 市区 | C15: 江门市新会爱尔新希望 | D15: 李小兰 | F15: 2 | G15: =VLOOKUP(A15,运维频率!A2:B299,2,FALSE) -> 2 | H15: =VLOOKUP(A15,上周期销售数据表!$A2:$O200,15,FALSE) -> 41 | I15: =VLOOKUP(A15,本周期销售数据表!$A2:$O200,15,FALSE) -> 40 | J15: =(I15-H15)/H15*100% -> -0.024390244 | K15: =VLOOKUP(A15,本周期销售数据表!$A2:$L200,10,FALSE) -> 408 | L15: =VLOOKUP(A15,本周期销售数据表!$A2:$L200,7,FALSE) -> 2 | AC15: =H15+20 -> 61 | AD15: =H15-20 -> 21
A16: 33525 | B16: 市区 | C16: 江门市蓬江交警 | D16: 李小兰 | F16: 2 | G16: =VLOOKUP(A16,运维频率!A2:B299,2,FALSE) -> 2 | H16: =VLOOKUP(A16,上周期销售数据表!$A2:$O200,15,FALSE) -> 18 | I16: =VLOOKUP(A16,本周期销售数据表!$A2:$O200,15,FALSE) -> 22 | J16: =(I16-H16)/H16*100% -> 0.22222222 | K16: =VLOOKUP(A16,本周期销售数据表!$A2:$L200,10,FALSE) -> 66.5 | L16: =VLOOKUP(A16,本周期销售数据表!$A2:$L200,7,FALSE) -> 1 | AC16: =H16+20 -> 38 | AD16: =H16-20 -> -2
A17: 23400 | B17: 市区 | C17: 江门市松下饭堂 | D17: 李小兰 | F17: 1 | G17: =VLOOKUP(A17,运维频率!A2:B299,2,FALSE) -> 1 | H17: =VLOOKUP(A17,上周期销售数据表!$A2:$O200,15,FALSE) -> 49 | I17: =VLOOKUP(A17,本周期销售数据表!$A2:$O200,15,FALSE) -> 57 | J17: =(I17-H17)/H17*100% -> 0.16326531 | K17: =VLOOKUP(A17,本周期销售数据表!$A2:$L200,10,FALSE) -> 356 | L17: =VLOOKUP(A17,本周期销售数据表!$A2:$L200,7,FALSE) -> 8 | AC17: =H17+20 -> 69 | AD17: =H17-20 -> 29
A18: 13444 | B18: 市区 | C18: 江门市行政总汇4楼 | D18: 李小兰 | F18: 1 | G18: =VLOOKUP(A18,运维频率!A2:B299,2,FALSE) -> 1 | H18: =VLOOKUP(A18,上周期销售数据表!$A2:$O200,15,FALSE) -> 19 | I18: =VLOOKUP(A18,本周期销售数据表!$A2:$O200,15,FALSE) -> 6 | J18: =(I18-H18)/H18*100% -> -0.68421053 | K18: =VLOOKUP(A18,本周期销售数据表!$A2:$L200,10,FALSE) -> 59 | L18: =VLOOKUP(A18,本周期销售数据表!$A2:$L200,7,FALSE) -> 0 | AC18: =H18+20 -> 39 | AD18: =H18-20 -> -1
A19: 21634 | B19: 市区 | C19: 江门市行政总汇3楼 | D19: 李小兰 | F19: 0 | G19: =VLOOKUP(A19,运维频率!A2:B299,2,FALSE) -> 0 | H19: =VLOOKUP(A19,上周期销售数据表!$A2:$O200,15,FALSE) -> #N/A | I19: =VLOOKUP(A19,本周期销售数据表!$A2:$O200,15,FALSE) -> #N/A | J19: =(I19-H19)/H19*100% -> #N/A | K19: =VLOOKUP(A19,本周期销售数据表!$A2:$L200,10,FALSE) -> #N/A | L19: =VLOOKUP(A19,本周期销售数据表!$A2:$L200,7,FALSE) -> #N/A | AC19: =H19+20 -> #N/A | AD19: =H19-20 -> #N/A
A20: 19391 | B20: 市区 | C20: 江门市中国移动通信信息楼 | D20: 李小兰 | F20: 0 | G20: =VLOOKUP(A20,运维频率!A2:B299,2,FALSE) -> 0 | H20: =VLOOKUP(A20,上周期销售数据表!$A2:$O200,15,FALSE) -> #N/A | I20: =VLOOKUP(A20,本周期销售数据表!$A2:$O200,15,FALSE) -> #N/A | J20: =(I20-H20)/H20*100% -> #N/A | K20: =VLOOKUP(A20,本周期销售数据表!$A2:$L200,10,FALSE) -> #N/A | L20: =VLOOKUP(A20,本周期销售数据表!$A2:$L200,7,FALSE) -> #N/A | AC20: =H20+20 -> #N/A | AD20: =H20-20 -> #N/A
A21: 16690 | B21: 市区 | C21: 江门市图书馆 | D21: 李小兰 | F21: 3 | G21: =VLOOKUP(A21,运维频率!A2:B299,2,FALSE) -> 2 | H21: =VLOOKUP(A21,上周期销售数据表!$A2:$O200,15,FALSE) -> 45 | I21: =VLOOKUP(A21,本周期销售数据表!$A2:$O200,15,FALSE) -> 97 | J21: =(I21-H21)/H21*100% -> 1.1555556 | K21: =VLOOKUP(A21,本周期销售数据表!$A2:$L200,10,FALSE) -> 463.5 | L21: =VLOOKUP(A21,本周期销售数据表!$A2:$L200,7,FALSE) -> 1 | AC21: =H21+20 -> 65 | AD21: =H21-20 -> 25
A22: 12268 | B22: 市区 | C22: 江门戴爱莲 | D22: 李小兰 | F22: 1 | G22: =VLOOKUP(A22,运维频率!A2:B299,2,FALSE) -> 1 | H22: =VLOOKUP(A22,上周期销售数据表!$A2:$O200,15,FALSE) -> 15 | I22: =VLOOKUP(A22,本周期销售数据表!$A2:$O200,15,FALSE) -> 8 | J22: =(I22-H22)/H22*100% -> -0.46666667 | K22: =VLOOKUP(A22,本周期销售数据表!$A2:$L200,10,FALSE) -> 64.6 | L22: =VLOOKUP(A22,本周期销售数据表!$A2:$L200,7,FALSE) -> 1 | AC22: =H22+20 -> 35 | AD22: =H22-20 -> -5
A23: 23479 | B23: 市区 | C23: 恩平中国电信 | D23: 张礼初 | F23: 0 | G23: =VLOOKUP(A23,运维频率!A2:B299,2,FALSE) -> 0 | H23: =VLOOKUP(A23,上周期销售数据表!$A2:$O200,15,FALSE) -> #N/A | I23: =VLOOKUP(A23,本周期销售数据表!$A2:$O200,15,FALSE) -> #N/A | J23: =(I23-H23)/H23*100% -> #N/A | K23: =VLOOKUP(A23,本周期销售数据表!$A2:$L200,10,FALSE) -> #N/A | L23: =VLOOKUP(A23,本周期销售数据表!$A2:$L200,7,FALSE) -> #N/A | AC23: =H23+20 -> #N/A | AD23: =H23-20 -> #N/A
A24: 12239 | B24: 市区 | C24: 江门市看守所 | D24: 李小兰 | F24: 1 | G24: =VLOOKUP(A24,运维频率!A2:B299,2,FALSE) -> 1 | H24: =VLOOKUP(A24,上周期销售数据表!$A2:$O200,15,FALSE) -> 38 | I24: =VLOOKUP(A24,本周期销售数据表!$A2:$O200,15,FALSE) -> 21 | J24: =(I24-H24)/H24*100% -> -0.44736842 | K24: =VLOOKUP(A24,本周期销售数据表!$A2:$L200,10,FALSE) -> 164.8 | L24: =VLOOKUP(A24,本周期销售数据表!$A2:$L200,7,FALSE) -> 4 | AC24: =H24+20 -> 58 | AD24: =H24-20 -> 18
A25: 12266 | B25: 市区 | C25: 江门供电局 | D25: 李小兰 | F25: 2 | G25: =VLOOKUP(A25,运维频率!A2:B299,2,FALSE) -> 2 | H25: =VLOOKUP(A25,上周期销售数据表!$A2:$O200,15,FALSE) -> 70 | I25: =VLOOKUP(A25,本周期销售数据表!$A2:$O200,15,FALSE) -> 79 | J25: =(I25-H25)/H25*100% -> 0.12857143 | K25: =VLOOKUP(A25,本周期销售数据表!$A2:$L200,10,FALSE) -> 281.05 | L25: =VLOOKUP(A25,本周期销售数据表!$A2:$L200,7,FALSE) -> 1 | AC25: =H25+20 -> 90 | AD25: =H25-20 -> 50
A26: 23398 | B26: 市区 | C26: 小榄服务区服务楼 | D26: 张礼初 | F26: 2 | G26: =VLOOKUP(A26,运维频率!A2:B299,2,FALSE) -> 1 | H26: =VLOOKUP(A26,上周期销售数据表!$A2:$O200,15,FALSE) -> 6 | I26: =VLOOKUP(A26,本周期销售数据表!$A2:$O200,15,FALSE) -> 9 | J26: =(I26-H26)/H26*100% -> 0.5 | K26: =VLOOKUP(A26,本周期销售数据表!$A2:$L200,10,FALSE) -> 130.3 | L26: =VLOOKUP(A26,本周期销售数据表!$A2:$L200,7,FALSE) -> 2 | AC26: =H26+20 -> 26 | AD26: =H26-20 -> -14
A27: 37604 | B27: 市区 | C27: 台山公安局 | D27: 卖机 | F27: 0 | G27: =VLOOKUP(A27,运维频率!A2:B299,2,FALSE) -> 0 | H27: =VLOOKUP(A27,上周期销售数据表!$A2:$O200,15,FALSE) -> 35 | I27: =VLOOKUP(A27,本周期销售数据表!$A2:$O200,15,FALSE) -> 40 | J27: =(I27-H27)/H27*100% -> 0.14285714 | K27: =VLOOKUP(A27,本周期销售数据表!$A2:$L200,10,FALSE) -> 151.5 | L27: =VLOOKUP(A27,本周期销售数据表!$A2:$L200,7,FALSE) -> 2 | AC27: =H27+20 -> 55 | AD27: =H27-20 -> 15
A28: 23401 | B28: 市区 | C28: 三江交警 | D28: 李小兰 | F28: 0 | G28: =VLOOKUP(A28,运维频率!A2:B299,2,FALSE) -> 1 | H28: =VLOOKUP(A28,上周期销售数据表!$A2:$O200,15,FALSE) -> 3 | I28: =VLOOKUP(A28,本周期销售数据表!$A2:$O200,15,FALSE) -> 0 | J28: =(I28-H28)/H28*100% -> -1 | K28: =VLOOKUP(A28,本周期销售数据表!$A2:$L200,10,FALSE) -> 0 | L28: =VLOOKUP(A28,本周期销售数据表!$A2:$L200,7,FALSE) -> 1 | AC28: =H28+20 -> 23 | AD28: =H28-20 -> -17
A29: 19823 | B29: 市区 | C29: 拘留所 | D29: 李小兰 | F29: 1 | G29: =VLOOKUP(A29,运维频率!A2:B299,2,FALSE) -> 1 | H29: =VLOOKUP(A29,上周期销售数据表!$A2:$O200,15,FALSE) -> 10 | I29: =VLOOKUP(A29,本周期销售数据表!$A2:$O200,15,FALSE) -> 11 | J29: =(I29-H29)/H29*100% -> 0.1 | K29: =VLOOKUP(A29,本周期销售数据表!$A2:$L200,10,FALSE) -> 50 | L29: =VLOOKUP(A29,本周期销售数据表!$A2:$L200,7,FALSE) -> 2 | AC29: =H29+20 -> 30 | AD29: =H29-20 -> -10
A30: 22254 | B30: 市区 | C30: 江门市办案中心 | D30: 李小兰 | F30: 1 | G30: =VLOOKUP(A30,运维频率!A2:B299,2,FALSE) -> 1 | H30: =VLOOKUP(A30,上周期销售数据表!$A2:$O200,15,FALSE) -> 10 | I30: =VLOOKUP(A30,本周期销售数据表!$A2:$O200,15,FALSE) -> 5 | J30: =(I30-H30)/H30*100% -> -0.5 | K30: =VLOOKUP(A30,本周期销售数据表!$A2:$L200,10,FALSE) -> 28 | L30: =VLOOKUP(A30,本周期销售数据表!$A2:$L200,7,FALSE) -> 1 | AC30: =H30+20 -> 30 | AD30: =H30-20 -> -10
A31: 39288 | B31: 市区 | C31: 南国学院图书馆新馆二楼 | D31: 卖机 | F31: 0 | G31: =VLOOKUP(A31,运维频率!A2:B299,2,FALSE) -> 0 | H31: =VLOOKUP(A31,上周期销售数据表!$A2:$O200,15,FALSE) -> 20 | I31: =VLOOKUP(A31,本周期销售数据表!$A2:$O200,15,FALSE) -> 20 | J31: =(I31-H31)/H31*100% -> 0 | K31: =VLOOKUP(A31,本周期销售数据表!$A2:$L200,10,FALSE) -> 169 | L31: =VLOOKUP(A31,本周期销售数据表!$A2:$L200,7,FALSE) -> 0 | AC31: =H31+20 -> 40 | AD31: =H31-20 -> 0
A32: 39289 | B32: 市区 | C32: 南国学院图书馆新馆三楼 | D32: 卖机 | F32: 0 | G32: =VLOOKUP(A32,运维频率!A2:B299,2,FALSE) -> 0 | H32: =VLOOKUP(A32,上周期销售数据表!$A2:$O200,15,FALSE) -> 32 | I32: =VLOOKUP(A32,本周期销售数据表!$A2:$O200,15,FALSE) -> 30 | J32: =(I32-H32)/H32*100% -> -0.0625 | K32: =VLOOKUP(A32,本周期销售数据表!$A2:$L200,10,FALSE) -> 269 | L32: =VLOOKUP(A32,本周期销售数据表!$A2:$L200,7,FALSE) -> 0 | AC32: =H32+20 -> 52 | AD32: =H32-20 -> 12
A33: 67234 | B33: 粤西 | C33: 粤西梁金山服务区南 | D33: 张礼初 | F33: 3 | G33: =VLOOKUP(A33,运维频率!A2:B299,2,FALSE) -> 1 | H33: =VLOOKUP(A33,上周期销售数据表!$A2:$O200,15,FALSE) -> 246 | I33: =VLOOKUP(A33,本周期销售数据表!$A2:$O200,15,FALSE) -> 114 | J33: =(I33-H33)/H33*100% -> -0.53658537 | K33: =VLOOKUP(A33,本周期销售数据表!A2:M200,10,FALSE) -> 1817.7 | L33: =VLOOKUP(A33,本周期销售数据表!A2:N200,7,FALSE) -> 2 | AC33: =H33+20 -> 266 | AD33: =H33-20 -> 226
A34: 22253 | B34: 市区 | C34: 鹤山中国电信 | D34: 李小兰 | F34: 2 | G34: =VLOOKUP(A34,运维频率!A2:B299,2,FALSE) -> 2 | H34: =VLOOKUP(A34,上周期销售数据表!$A2:$O200,15,FALSE) -> 10 | I34: =VLOOKUP(A34,本周期销售数据表!$A2:$O200,15,FALSE) -> 6 | J34: =(I34-H34)/H34*100% -> -0.4 | K34: =VLOOKUP(A34,本周期销售数据表!$A2:$L200,10,FALSE) -> 25.3 | L34: =VLOOKUP(A34,本周期销售数据表!$A2:$L200,7,FALSE) -> 0 | AC34: =H34+20 -> 30 | AD34: =H34-20 -> -10
A35: 12241 | B35: 粤西 | C35: 粤西新墟服务区南 | D35: 张礼初 | F35: 1 | G35: =VLOOKUP(A35,运维频率!A2:B299,2,FALSE) -> 2 | H35: =VLOOKUP(A35,上周期销售数据表!$A2:$O200,15,FALSE) -> 55 | I35: =VLOOKUP(A35,本周期销售数据表!$A2:$O200,15,FALSE) -> 19 | J35: =(I35-H35)/H35*100% -> -0.65454545 | K35: =VLOOKUP(A35,本周期销售数据表!$A2:$L200,10,FALSE) -> 266 | L35: =VLOOKUP(A35,本周期销售数据表!$A2:$L200,7,FALSE) -> 0 | AC35: =H35+20 -> 75 | AD35: =H35-20 -> 35
A36: 12256 | B36: 粤西 | C36: 粤西新墟服务区北 | D36: 张礼初 | F36: 1 | G36: =VLOOKUP(A36,运维频率!A2:B299,2,FALSE) -> 2 | H36: =VLOOKUP(A36,上周期销售数据表!$A3:$O201,15,FALSE) -> 8 | I36: =VLOOKUP(A36,本周期销售数据表!$A2:$O200,15,FALSE) -> 2 | J36: =(I36-H36)/H36*100% -> -0.75 | K36: =VLOOKUP(A36,本周期销售数据表!$A2:$L200,10,FALSE) -> 33.6 | L36: =VLOOKUP(A36,本周期销售数据表!$A2:$L200,7,FALSE) -> 2 | AC36: =H36+20 -> 28 | AD36: =H36-20 -> -12
A37: 20770 | B37: 粤西 | C37: 粤西司前服务区南 | D37: 张礼初 | F37: 2 | G37: =VLOOKUP(A37,运维频率!A2:B299,2,FALSE) -> 2 | H37: =VLOOKUP(A37,上周期销售数据表!$A2:$O200,15,FALSE) -> 75 | I37: =VLOOKUP(A37,本周期销售数据表!$A2:$O200,15,FALSE) -> 27 | J37: =(I37-H37)/H37*100% -> -0.64 | K37: =VLOOKUP(A37,本周期销售数据表!$A2:$L200,10,FALSE) -> 417.3 | L37: =VLOOKUP(A37,本周期销售数据表!$A2:$L200,7,FALSE) -> 5 | AC37: =H37+20 -> 95 | AD37: =H37-20 -> 55
A38: 12267 | B38: 粤西 | C38: 粤西司前服务区北 | D38: 张礼初 | F38: 2 | G38: =VLOOKUP(A38,运维频率!A2:B299,2,FALSE) -> 2 | H38: =VLOOKUP(A38,上周期销售数据表!$A2:$O200,15,FALSE) -> 30 | I38: =VLOOKUP(A38,本周期销售数据表!$A2:$O200,15,FALSE) -> 34 | J38: =(I38-H38)/H38*100% -> 0.13333333 | K38: =VLOOKUP(A38,本周期销售数据表!$A2:$L200,10,FALSE) -> 514.6 | L38: =VLOOKUP(A38,本周期销售数据表!$A2:$L200,7,FALSE) -> 6 | AC38: =H38+20 -> 50 | AD38: =H38-20 -> 10
A39: 18871 | B39: 粤西 | C39: 粤西阳江服务区南 | D39: 张礼初 | F39: 2 | G39: =VLOOKUP(A39,运维频率!A2:B299,2,FALSE) -> 2 | H39: =VLOOKUP(A39,上周期销售数据表!$A2:$O200,15,FALSE) -> 168 | I39: =VLOOKUP(A39,本周期销售数据表!$A2:$O200,15,FALSE) -> 49 | J39: =(I39-H39)/H39*100% -> -0.70833333 | K39: =VLOOKUP(A39,本周期销售数据表!$A2:$L200,10,FALSE) -> 757.4 | L39: =VLOOKUP(A39,本周期销售数据表!$A2:$L200,7,FALSE) -> 1 | AC39: =H39+20 -> 188 | AD39: =H39-20 -> 148
A40: 22219 | B40: 粤西 | C40: 粤西阳江服务区北 | D40: 张礼初 | F40: 2 | G40: =VLOOKUP(A40,运维频率!A2:B299,2,FALSE) -> 2 | H40: =VLOOKUP(A40,上周期销售数据表!$A2:$O200,15,FALSE) -> 40 | I40: =VLOOKUP(A40,本周期销售数据表!$A2:$O200,15,FALSE) -> 40 | J40: =(I40-H40)/H40*100% -> 0 | K40: =VLOOKUP(A40,本周期销售数据表!$A2:$L200,10,FALSE) -> 596.3 | L40: =VLOOKUP(A40,本周期销售数据表!$A2:$L200,7,FALSE) -> 0 | AC40: =H40+20 -> 60 | AD40: =H40-20 -> 20
...

Sheet 本周期销售数据表
A1: 机器编号 | B1: 点位名称 | C1: 线上杯数 | D1: 线上金额 | E1: 线下杯数 | F1: 线下金额 | G1: 测试杯 | H1: 免费杯 | I1: 总杯数 | J1: 总金额 | K1: 线上销售比例 | L1: 线下销售比例 | O1: 实际销售杯数
A2: 12268 | B2: 江门戴爱莲 | C2: 2 | D2: 17.2 | E2: 6 | F2: 47.4 | G2: 1 | H2: 0 | I2: 9 | J2: 64.6 | K2: 0.2663 | L2: 0.7337 | O2: =I2-G2-H2 -> 8
A3: 12248 | B3: 江门市中心医院外科4楼手术室 | C3: 19 | D3: 197.8 | E3: 9 | F3: 82 | G3: 2 | H3: 0 | I3: 30 | J3: 279.8 | K3: 0.7069 | L3: 0.2931 | O3: =I3-G3-H3 -> 28
A4: 13441 | B4: 江门市购书中心 | C4: 0 | D4: 0 | E4: 5 | F4: 54 | G4: 1 | H4: 0 | I4: 6 | J4: 54 | K4: 0 | L4: 1 | O4: =I4-G4-H4 -> 5
A5: 13444 | B5: 江门市行政总汇4楼 | C5: 5 | D5: 48.2 | E5: 1 | F5: 10.8 | G5: 0 | H5: 0 | I5: 6 | J5: 59 | K5: 0.8169 | L5: 0.1831 | O5: =I5-G5-H5 -> 6
A6: 18871 | B6: 粤西阳江服务区南区 | C6: 34 | D6: 521.4 | E6: 15 | F6: 236 | G6: 1 | H6: 0 | I6: 50 | J6: 757.4 | K6: 0.6884 | L6: 0.3116 | O6: =I6-G6-H6 -> 49
A7: 18878 | B7: 珠三角斗门服务区南区 | C7: 11 | D7: 167.9 | E7: 6 | F7: 96.8 | G7: 0 | H7: 0 | I7: 17 | J7: 264.7 | K7: 0.6343 | L7: 0.3657 | O7: =I7-G7-H7 -> 17
A8: 19662 | B8: 江门市新会中医院2号楼大堂 | C8: 2 | D8: 0 | E8: 3 | F8: 30.4 | G8: 3 | H8: 0 | I8: 8 | J8: 30.4 | K8: 0 | L8: 1 | O8: =I8-G8-H8 -> 5
A9: 22335 | B9: 元山服务区西区 | C9: 7 | D9: 91.3 | E9: 2 | F9: 33.6 | G9: 1 | H9: 0 | I9: 10 | J9: 124.9 | K9: 0.731 | L9: 0.269 | O9: =I9-G9-H9 -> 9
A10: 22340 | B10: 元山服务区东区 | C10: 20 | D10: 275.4 | E10: 15 | F10: 227 | G10: 2 | H10: 0 | I10: 37 | J10: 502.4 | K10: 0.5482 | L10: 0.4518 | O10: =I10-G10-H10 -> 35
A11: 27748 | B11: 珠三角斗门服务区北区 | C11: 16 | D11: 211.3 | E11: 12 | F11: 177.6 | G11: 0 | H11: 0 | I11: 28 | J11: 388.9 | K11: 0.5433 | L11: 0.4567 | O11: =I11-G11-H11 -> 28
A12: 20858 | B12: 珠三角南沙服务区北区 | C12: 20 | D12: 281.9 | E12: 5 | F12: 80 | G12: 1 | H12: 0 | I12: 26 | J12: 361.9 | K12: 0.7789 | L12: 0.2211 | O12: =I12-G12-H12 -> 25
A13: 23398 | B13: 珠三角南沙服务区南区 | C13: 5 | D13: 66.1 | E13: 4 | F13: 64.2 | G13: 2 | H13: 0 | I13: 11 | J13: 130.3 | K13: 0.5073 | L13: 0.4927 | O13: =I13-G13-H13 -> 9
... A165: 33426 | B165: 清远图书馆旧馆 | C165: 19 | D165: 172.8 | E165: 11 | F165: 117.2 | G165: 0 | H165: 0 | I165: 30 | J165: 290 | K165: 0.5959 | L165: 0.4041 | O165: =I165-G165-H165 -> 30
O166: =I166-G166-H166 -> 0
O167: =I167-G167-H167 -> 0
O168: =I168-G168-H168 -> 0
O169: =I169-G169-H169 -> 0
O170: =I170-G170-H170 -> 0
O171: =I171-G171-H171 -> 0
O172: =I172-G172-H172 -> 0
O173: =I173-G173-H173 -> 0
O174: =I174-G174-H174 -> 0

Sheet 上周期销售数据表
A1: 机器编号 | B1: 点位名称 | C1: 线上杯数 | D1: 线上金额 | E1: 线下杯数 | F1: 线下金额 | G1: 测试杯 | H1: 免费杯 | I1: 总杯数 | J1: 总金额 | K1: 线上销售比例 | L1: 线下销售比例 | O1: 实际售出杯数
A2: 12268 | B2: 江门戴爱莲 | C2: 7 | D2: 58.6 | E2: 8 | F2: 63 | G2: 3 | H2: 0 | I2: 18 | J2: 121.6 | K2: 0.4819 | L2: 0.5181 | O2: =I2-G2-H2 -> 15
A3: 12248 | B3: 江门市中心医院外科4楼手术室 | C3: 13 | D3: 127 | E3: 12 | F3: 125.8 | G3: 1 | H3: 0 | I3: 26 | J3: 252.8 | K3: 0.5024 | L3: 0.4976 | O3: =I3-G3-H3 -> 25
A4: 13441 | B4: 江门市购书中心 | C4: 4 | D4: 10.8 | E4: 8 | F4: 82.6 | G4: 1 | H4: 0 | I4: 13 | J4: 93.4 | K4: 0.1156 | L4: 0.8844 | O4: =I4-G4-H4 -> 12
A5: 13444 | B5: 江门市行政总汇4楼 | C5: 7 | D5: 75.6 | E5: 12 | F5: 118.2 | G5: 2 | H5: 0 | I5: 21 | J5: 193.8 | K5: 0.3901 | L5: 0.6099 | O5: =I5-G5-H5 -> 19
A6: 18871 | B6: 粤西阳江服务区南区 | C6: 108 | D6: 1504.8 | E6: 60 | F6: 958 | G6: 2 | H6: 0 | I6: 170 | J6: 2462.8 | K6: 0.611 | L6: 0.389 | O6: =I6-G6-H6 -> 168
A7: 18878 | B7: 珠三角斗门服务区南区 | C7: 18 | D7: 259.5 | E7: 18 | F7: 269.4 | G7: 3 | H7: 0 | I7: 39 | J7: 528.9 | K7: 0.4906 | L7: 0.5094 | O7: =I7-G7-H7 -> 36
A8: 19662 | B8: 江门市新会中医院2号楼大堂 | C8: 18 | D8: 188.8 | E8: 4 | F8: 37.2 | G8: 3 | H8: 0 | I8: 25 | J8: 226 | K8: 0.8354 | L8: 0.1646 | O8: =I8-G8-H8 -> 22
A9: 22335 | B9: 元山服务区西区 | C9: 34 | D9: 476.9 | E9: 14 | F9: 220.2 | G9: 7 | H9: 0 | I9: 55 | J9: 697.1 | K9: 0.6841 | L9: 0.3159 | O9: =I9-G9-H9 -> 48
A10: 22340 | B10: 元山服务区东区 | C10: 29 | D10: 403.7 | E10: 18 | F10: 275.4 | G10: 1 | H10: 0 | I10: 48 | J10: 679.1 | K10: 0.5945 | L10: 0.4055 | O10: =I10-G10-H10 -> 47
A11: 27748 | B11: 珠三角斗门服务区北区 | C11: 11 | D11: 157.4 | E11: 4 | F11: 63.2 | G11: 2 | H11: 0 | I11: 17 | J11: 220.6 | K11: 0.7135 | L11: 0.2865 | O11: =I11-G11-H11 -> 15
A12: 20858 | B12: 珠三角南沙服务区北区 | C12: 2 | D12: 23.7 | E12: 0 | F12: 0 | G12: 0 | H12: 0 | I12: 2 | J12: 23.7 | K12: 1 | L12: 0 | O12: =I12-G12-H12 -> 2
A13: 20857 | B13: 珠三角南沙服务区南区 | C13: 36 | D13: 511.6 | E13: 24 | F13: 361.2 | G13: 0 | H13: 0 | I13: 60 | J13: 872.8 | K13: 0.5862 | L13: 0.4138 | O13: =I13-G13-H13 -> 60
... A28: 33427 | B28: 粤西新城服务区南区 | C28: 45 | D28: 620 | E28: 28 | F28: 438.4 | G28: 0 | H28: 0 | I28: 73 | J28: 1058.4 | K28: 0.5858 | L28: 0.4142 | O28: =I28-G28-H28 -> 73
B29: 清远人民医院2号住院楼 | C29: 3 | D29: 23.2 | E29: 6 | F29: 62 | G29: 0 | H29: 0 | I29: 9 | J29: 85.2 | K29: 0.2723 | L29: 0.7277 | O29: =I29-G29-H29 -> 9
A30: 33416 | B30: 粤北梅花北服务区北区 | C30: 4 | D30: 47.4 | E30: 5 | F30: 77 | G30: 1 | H30: 0 | I30: 10 | J30: 124.4 | K30: 0.381 | L30: 0.619 | O30: =I30-G30-H30 -> 9
A31: 33418 | B31: 粤北梅花北服务区南区 | C31: 13 | D31: 186.5 | E31: 16 | F31: 237.8 | G31: 2 | H31: 0 | I31: 31 | J31: 424.3 | K31: 0.4395 | L31: 0.5605 | O31: =I31-G31-H31 -> 29
B32: 清远人民医院1号住院楼 | C32: 0 | D32: 0 | E32: 1 | F32: 10.8 | G32: 0 | H32: 0 | I32: 1 | J32: 10.8 | K32: 0 | L32: 1 | O32: =I32-G32-H32 -> 1
A33: 33412 | B33: 清远人民医院门诊 | C33: 16 | D33: 144.1 | E33: 19 | F33: 203.6 | G33: 0 | H33: 0 | I33: 35 | J33: 347.7 | K33: 0.4144 | L33: 0.5856 | O33: =I33-G33-H33 -> 35
A34: 33417 | B34: 中山大学附属第三医院肇庆医院 | C34: 34 | D34: 329.8 | E34: 16 | F34: 155.2 | G34: 2 | H34: 0 | I34: 52 | J34: 485 | K34: 0.68 | L34: 0.32 | O34: =I34-G34-H34 -> 50
A35: 33516 | B35: 中山市税务局南楼2楼 | C35: 0 | D35: 0 | E35: 4 | F35: 20.8 | G35: 1 | H35: 0 | I35: 5 | J35: 20.8 | K35: 0 | L35: 1 | O35: =I35-G35-H35 -> 4
A36: 33430 | B36: 粤北英德服务区南区 | C36: 26 | D36: 329.6 | E36: 14 | F36: 219.2 | G36: 2 | H36: 0 | I36: 42 | J36: 548.8 | K36: 0.6006 | L36: 0.3994 | O36: =I36-G36-H36 -> 40
A37: 33512 | B37: 粤北英德服务区北区 | C37: 12 | D37: 155.9 | E37: 5 | F37: 76 | G37: 1 | H37: 0 | I37: 18 | J37: 231.9 | K37: 0.6723 | L37: 0.3277 | O37: =I37-G37-H37 -> 17
A38: 33511 | B38: 粤北花城服务区 | C38: 1 | D38: 14.8 | E38: 1 | F38: 15.8 | G38: 2 | H38: 0 | I38: 4 | J38: 30.6 | K38: 0.4837 | L38: 0.5163 | O38: =I38-G38-H38 -> 2
A39: 33514 | B39: 粤北源潭服务区 | C39: 21 | D39: 290.2 | E39: 6 | F39: 91.8 | G39: 6 | H39: 0 | I39: 33 | J39: 382 | K39: 0.7597 | L39: 0.2403 | O39: =I39-G39-H39 -> 27
A40: 33413 | B40: 粤北乐昌服务区南区 | C40: 50 | D40: 642.7 | E40: 37 | F40: 563.6 | G40: 2 | H40: 0 | I40: 89 | J40: 1206.3 | K40: 0.5328 | L40: 0.4672 | O40: =I40-G40-H40 -> 87
A41: 33515 | B41: 恩平妇幼门诊大堂 | C41: 7 | D41: 67.8 | E41: 7 | F41: 67.8 | G41: 0 | H41: 0 | I41: 14 | J41: 135.6 | K41: 0.5 | L41: 0.5 | O41: =I41-G41-H41 -> 14
A42: 33513 | B42: 粤西圣堂服务区北区 | C42: 58 | D42: 732.8 | E42: 10 | F42: 150 | G42: 2 | H42: 0 | I42: 70 | J42: 882.8 | K42: 0.8301 | L42: 0.1699 | O42: =I42-G42-H42 -> 68
A43: 66331 | B43: 粤西圣堂服务区南区 | C43: 148 | D43: 2058.3 | E43: 47 | F43: 755.6 | G43: 0 | H43: 0 | I43: 195 | J43: 2813.9 | K43: 0.7315 | L43: 0.2685 | O43: =I43-G43-H43 -> 195
A44: 33524 | B44: 顺德宏石激光2楼 | C44: 5 | D44: 34 | E44: 27 | F44: 176 | G44: 0 | H44: 0 | I44: 32 | J44: 210 | K44: 0.1619 | L44: 0.8381 | O44: =I44-G44-H44 -> 32
... A167: 33426 | B167: 清远图书馆旧馆 | C167: 11 | D167: 98.4 | E167: 2 | F167: 21.6 | G167: 18 | H167: 0 | I167: 31 | J167: 120 | K167: 0.82 | L167: 0.18 | O167: =I167-G167-H167 -> 13
O168: =I168-G168-H168 -> 0
O169: =I169-G169-H169 -> 0
O170: =I170-G170-H170 -> 0
O171: =I171-G171-H171 -> 0
O172: =I172-G172-H172 -> 0
O173: =I173-G173-H173 -> 0
O174: =I174-G174-H174 -> 0
O175: =I175-G175-H175 -> 0
O176: =I176-G176-H176 -> 0
...

Sheet 运维数据
A1: 站点 | B1: 机身码 | C1: 站点 | D1: 所属区域 （可以扫码录入）
B2: 79339
B3: 33679
B4: 33687
B5: 12241
B6: 12256
B7: 67235
B8: 68718
B9: 66130
B10: 52944
B11: 33416
B12: 33427
B13: 33422
... B232: 68852

Sheet 运维频率
A1: 机身码 | B1: 重复次数
A2: 12248 | B2: 2
A3: 18890 | B3: 3
A4: 51776 | B4: 4
A5: 52935 | B5: 2
A6: 35948 | B6: 3
A7: 74081 | B7: 1
A8: 19712 | B8: 0
A9: 19662 | B9: 1
A10: 68720 | B10: 2
A11: 68721 | B11: 3
A12: 13441 | B12: 1
A13: 26039 | B13: 2
... A179: 71352 | B179: 2

Sheet 初
A1: 机器编号 | B1: 线路 | C1: 点位名称 | D1: 所属督导 | E1: 运维人 | F1: 上周运维频率（次） | G1: 本周运维频率（次） | H1: 上周期总杯数 | I1: 本周期总杯数 | J1: 差异% | K1: 总金额 | L1: 测试杯 | M1: 停机时长 | N1: 停机原因备注 | O1: 投诉总量 | P1: 投诉率 | Q1: 缺料故障情况 | R1: 客户投诉 | S1: 异常事件 | T1: 事件备注
A2: 33279 | B2: 粤西 | C2: 粤西雷州服务区西区 | D2: 张礼初 | F2: 2 | G2: 3 | H2: 38 | I2: 30 | J2: -0.21052632 | K2: 429.4 | L2: 7 | AC2: 58 | AD2: 18
A3: 12256 | B3: 粤西 | C3: 粤西新墟服务区北 | D3: 张礼初 | F3: 1 | G3: 2 | H3: 8 | I3: 2 | J3: -0.75 | K3: 33.6 | L3: 2 | AC3: 28 | AD3: -12
A4: 33520 | B4: 中山 | C4: 中山市税务局三乡税局 | D4: 张礼初 | F4: 1 | G4: 2 | H4: 8 | I4: 5 | J4: -0.375 | K4: 24.7 | L4: 0
A5: 19393 | B5: 中山 | C5: 中山市税务局北楼 | D5: 张礼初 | F5: 3 | G5: 2 | H5: 11 | I5: 7 | J5: -0.36363636 | K5: 31.5 | L5: 0 | AC5: 31 | AD5: -9
A6: 33522 | B6: 中山 | C6: 中山市妇女儿童活动中心 | D6: 张礼初 | F6: 2 | G6: 2 | H6: 16 | I6: 11 | J6: -0.3125 | K6: 111.2 | L6: 0
A7: 33428 | B7: 粤西 | C7: 粤西播植服务区南区 | D7: 张礼初 | F7: 1 | G7: 2 | H7: 31 | I7: 14 | J7: -0.5483871 | K7: 213.2 | L7: 6 | AC7: 51 | AD7: 11
A8: 33423 | B8: 粤西 | C8: 粤西播植服务区北 | D8: 张礼初 | F8: 1 | G8: 2 | H8: 6 | I8: 14 | J8: 1.3333333 | K8: 210.8 | L8: 2 | AC8: 26 | AD8: -14
A9: 20905 | B9: 粤西 | C9: 粤西官渡服务区南区 | D9: 张礼初 | F9: 1 | G9: 2 | H9: 48 | I9: 15 | J9: -0.6875 | K9: 205.8 | L9: 1 | AC9: 68 | AD9: 28
A10: 18878 | B10: 珠三角 | C10: 珠三角斗门服务区南区 | D10: 张礼初 | F10: 1 | G10: 2 | H10: 36 | I10: 17 | J10: -0.52777778 | K10: 264.7 | L10: 0 | AC10: 56 | AD10: 16
A11: 22462 | B11: 中山 | C11: 中山市中国建设银行 | D11: 张礼初 | F11: 2 | G11: 2 | H11: 15 | I11: 17 | J11: 0.13333333 | K11: 75.85 | L11: 0 | AC11: 35 | AD11: -5
A12: 12241 | B12: 粤西 | C12: 粤西新墟服务区南 | D12: 张礼初 | F12: 1 | G12: 2 | H12: 55 | I12: 19 | J12: -0.65454545 | K12: 266 | L12: 0 | AC12: 75 | AD12: 35
A13: 29354 | B13: 粤西 | C13: 粤西苹塘服务区南 | D13: 张礼初 | F13: 2 | G13: 2 | H13: 40 | I13: 20 | J13: -0.5 | K13: 281.4 | L13: 3 | AC13: 60 | AD13: 20
A14: 33422 | B14: 粤西 | C14: 粤西安塘服务区北 | D14: 张礼初 | F14: 2 | G14: 2 | H14: 23 | I14: 22 | J14: -0.043478261 | K14: 326.3 | L14: 6 | AC14: 43 | AD14: 3
A15: 33424 | B15: 粤西 | C15: 粤西新城服务区北 | D15: 张礼初 | F15: 2 | G15: 2 | H15: 34 | I15: 22 | J15: -0.35294118 | K15: 285.9 | L15: 3 | AC15: 54 | AD15: 14
A16: 58987 | B16: 中山 | C16: 横栏服务区 | D16: 张礼初 | F16: 1 | G16: 2 | H16: 27 | I16: 25 | J16: -0.074074074 | K16: 463.64 | L16: 0
A17: 20770 | B17: 粤西 | C17: 粤西司前服务区南 | D17: 张礼初 | F17: 2 | G17: 2 | H17: 75 | I17: 27 | J17: -0.64 | K17: 417.3 | L17: 5 | AC17: 95 | AD17: 55
A18: 22176 | B18: 粤西 | C18: 粤西浅水服务区北区 | D18: 张礼初 | F18: 1 | G18: 2 | H18: 29 | I18: 27 | J18: -0.068965517 | K18: 375.1 | L18: 0 | AC18: 49 | AD18: 9
A19: 27748 | B19: 珠三角 | C19: 珠三角斗门服务区北区 | D19: 张礼初 | F19: 1 | G19: 2 | H19: 15 | I19: 28 | J19: 0.86666667 | K19: 388.9 | L19: 0 | AC19: 35 | AD19: -5
A20: 33427 | B20: 粤西 | C20: 粤西新城服务区南 | D20: 张礼初 | F20: 2 | G20: 2 | H20: 73 | I20: 31 | J20: -0.57534247 | K20: 451.7 | L20: 2 | AC20: 93 | AD20: 53
A21: 26986 | B21: 粤西 | C21: 粤西浅水服务区南区 | D21: 张礼初 | F21: 2 | G21: 2 | H21: 85 | I21: 32 | J21: -0.62352941 | K21: 460.5 | L21: 0 | AC21: 105 | AD21: 65
A22: 12267 | B22: 粤西 | C22: 粤西司前服务区北 | D22: 张礼初 | F22: 2 | G22: 2 | H22: 30 | I22: 34 | J22: 0.13333333 | K22: 514.6 | L22: 6 | AC22: 50 | AD22: 10
A23: 29355 | B23: 粤西 | C23: 粤西苹塘服务区北 | D23: 张礼初 | F23: 2 | G23: 2 | H23: 22 | I23: 35 | J23: 0.59090909 | K23: 503 | L23: 5 | AC23: 42 | AD23: 2
A24: 33420 | B24: 粤西 | C24: 粤西安塘服务区南 | D24: 张礼初 | F24: 1 | G24: 2 | H24: 67 | I24: 35 | J24: -0.47761194 | K24: 483.7 | L24: 6 | AC24: 87 | AD24: 47
A25: 22461 | B25: 珠三角 | C25: 珠三角龙口服务区东区 | D25: 张礼初 | F25: 2 | G25: 2 | H25: 29 | I25: 36 | J25: 0.24137931 | K25: 513.3 | L25: 31 | AC25: 49 | AD25: 9
A26: 85127 | B26: 粤西 | C26: 粤西柏桥服务区东区 | D26: 张礼初 | F26: 1 | G26: 2 | H26: 65 | I26: 36 | J26: -0.44615385 | K26: 483.2 | L26: 0
A27: 26990 | B27: 粤西 | C27: 粤西雷州服务区东区 | D27: 张礼初 | F27: 2 | G27: 2 | H27: 54 | I27: 38 | J27: -0.2962963 | K27: 515.4 | L27: 0 | AC27: 74 | AD27: 34
A28: 22219 | B28: 粤西 | C28: 粤西阳江服务区北 | D28: 张礼初 | F28: 2 | G28: 2 | H28: 40 | I28: 40 | J28: 0 | K28: 596.3 | L28: 0 | AC28: 60 | AD28: 20
A29: 18871 | B29: 粤西 | C29: 粤西阳江服务区南 | D29: 张礼初 | F29: 2 | G29: 2 | H29: 168 | I29: 49 | J29: -0.70833333 | K29: 757.4 | L29: 1 | AC29: 188 | AD29: 148
A30: 20903 | B30: 珠三角 | C30: 珠三角龙口服务区西区 | D30: 张礼初 | F30: 2 | G30: 2 | H30: 75 | I30: 51 | J30: -0.32 | K30: 760.5 | L30: 5 | AC30: 95 | AD30: 55
A31: 33417 | B31: 肇庆 | C31: 中山大学附属第三医院肇庆医院 | D31: 张礼初 | F31: 2 | G31: 2 | H31: 50 | I31: 60 | J31: 0.2 | K31: 588 | L31: 3 | AC31: 70 | AD31: 30
A32: 66331 | B32: 粤西 | C32: 粤西圣堂服务区南区 | D32: 张礼初 | F32: 2 | G32: 2 | H32: 195 | I32: 60 | J32: -0.69230769 | K32: 917.9 | L32: 0 | AC32: 215 | AD32: 175
A33: 33513 | B33: 粤西 | C33: 粤西圣堂服务区北 | D33: 张礼初 | F33: 2 | G33: 2 | H33: 68 | I33: 96 | J33: 0.41176471 | K33: 1387 | L33: 0 | AC33: 88 | AD33: 48
A34: 33516 | B34: 中山 | C34: 中山市税务局南楼 | D34: 张礼初 | F34: 2 | G34: 1 | H34: 4 | I34: 8 | J34: 1 | K34: 38.1 | L34: 0 | AC34: 24 | AD34: -16
A35: 23398 | B35: 市区 | C35: 小榄服务区服务楼 | D35: 张礼初 | F35: 2 | G35: 1 | H35: 6 | I35: 9 | J35: 0.5 | K35: 130.3 | L35: 2 | AC35: 26 | AD35: -14
A36: 33515 | B36: 恩平 | C36: 恩平妇幼门诊大堂 | D36: 张礼初 | F36: 2 | G36: 1 | H36: 14 | I36: 9 | J36: -0.35714286 | K36: 97.2 | L36: 0 | AC36: 34 | AD36: -6
A37: 30012 | B37: 粤西 | C37: 粤西官渡服务区北区 | D37: 张礼初 | F37: 1 | G37: 1 | H37: 14 | I37: 11 | J37: -0.21428571 | K37: 155.1 | L37: 1 | AC37: 34 | AD37: -6
A38: 33526 | B38: 珠三角 | C38: 珠三角蚬岗服务区南向 | D38: 张礼初 | F38: 1 | G38: 1 | H38: 25 | I38: 15 | J38: -0.4 | K38: 223.6 | L38: 2 | AC38: 45 | AD38: 5
... A42: 22247 | B42: 粤西 | C42: 粤西阳西服务区南 | D42: 张礼初 | F42: 0 | G42: 1 | H42: 106 | I42: 25 | J42: -0.76415094 | K42: 348.5 | L42: 1 | AC42: 126 | AD42: 86
A43: 23550 | B43: 中山 | C43: 小榄服务区服务大厅 | D43: 张礼初 | F43: 2 | G43: 1 | H43: 41 | I43: 28 | J43: -0.31707317 | K43: 377.6 | L43: 5
...

Sheet 烽
A1: 机器编号 | B1: 线路 | C1: 点位名称 | D1: 所属督导 | E1: 运维人 | F1: 上周运维频率（次） | G1: 本周运维频率（次） | H1: 上周期总杯数 | I1: 本周期总杯数 | J1: 差异% | K1: 总金额 | L1: 测试杯 | M1: 停机时长 | N1: 停机原因备注 | O1: 投诉总量 | P1: 投诉率 | Q1: 缺料故障情况 | R1: 客户投诉 | S1: 异常事件 | T1: 事件备注
A2: 67235 | B2: 东莞 | C2: 东莞妇幼门诊2楼 | D2: 黄梓烽 | F2: 2 | G2: 2 | H2: 45 | I2: 50 | J2: 0.11111111 | K2: 588.88 | L2: 0 | AC2: 65 | AD2: 25
A3: 68718 | B3: 东莞 | C3: 东莞妇幼门诊4楼 | D3: 黄梓烽 | F3: 2 | G3: 2 | H3: 22 | I3: 22 | J3: 0 | K3: 246.68 | L3: 0 | AC3: 42 | AD3: 2
A4: 66130 | B4: 东莞 | C4: 东莞妇幼综合楼 | D4: 黄梓烽 | F4: 2 | G4: 2 | H4: 16 | I4: 30 | J4: 0.875 | K4: 316.7 | L4: 0 | AC4: 36 | AD4: -4
A5: 68719 | B5: 佛山 | C5: 佛山安得智联 | D5: 黄梓烽 | F5: 3 | G5: 2 | H5: 55 | I5: 64 | J5: 0.16363636 | K5: 192 | L5: 2 | AC5: 75 | AD5: 35
A6: 71352 | B6: 广州 | C6: 广州市白云区图书馆 | D6: 黄梓烽 | F6: 0 | G6: 2 | H6: 51 | I6: 86 | J6: 0.68627451 | K6: 645.13 | L6: 66
A7: 79338 | B7: 广州 | C7: 广州市海珠图书馆 | D7: 黄梓烽 | F7: 2 | G7: 2 | H7: 21 | I7: 16 | J7: -0.23809524 | K7: 151.5 | L7: 4
A8: 79339 | B8: 广州 | C8: 广州市荔湾图书馆 | D8: 黄梓烽 | F8: 2 | G8: 2 | H8: 14 | I8: 20 | J8: 0.42857143 | K8: 209.5 | L8: 0 | AC8: 34 | AD8: -6
A9: 33431 | B9: 广州 | C9: 广州市斯洛特健身房（爱都店） | D9: 黄梓烽 | F9: 0 | G9: 0 | H9: #N/A | I9: #N/A | J9: #N/A | K9: #N/A | L9: #N/A
A10: 26039 | B10: 市区 | C10: 广州市孙逸仙花都区急诊 | D10: 黄梓烽 | F10: 1 | G10: 2 | H10: 11 | I10: 10 | J10: -0.090909091 | K10: 110 | L10: 1 | AC10: 31 | AD10: -9
A11: 68717 | B11: 广州 | C11: 广州市孙逸仙花都区住院部一楼 | D11: 黄梓烽 | F11: 1 | G11: 2 | H11: 11 | I11: 11 | J11: 0 | K11: 127 | L11: 3
A12: 33280 | B12: 广州 | C12: 广州市孙逸仙南院区逸仙楼18楼全科科室 | D12: 黄梓烽 | F12: 2 | G12: 2 | H12: 8 | I12: 25 | J12: 2.125 | K12: 208.8 | L12: 2
A13: 68715 | B13: 广州 | C13: 广州市孙逸仙南院区住院一楼 | D13: 黄梓烽 | F13: 2 | G13: 2 | H13: 50 | I13: 54 | J13: 0.08 | K13: 613 | L13: 2
A14: 53117 | B14: 租机2 | C14: 广州市通驿大院 | D14: 黄梓烽 | F14: 0 | G14: 2 | H14: 1 | I14: 4 | J14: 3 | K14: 26 | L14: 4
A15: 67236 | B15: 华通 | C15: 华通龙山服务区东区 | D15: 黄梓烽 | F15: 2 | G15: 2 | H15: 7 | I15: 14 | J15: 1 | K15: 190.5 | L15: 0 | AC15: 27 | AD15: -13
A16: 66333 | B16: 华通 | C16: 华通龙山服务区西区 | D16: 黄梓烽 | F16: 1 | G16: 2 | H16: 37 | I16: 16 | J16: -0.56756757 | K16: 227.1 | L16: 0 | AC16: 57 | AD16: 17
A17: 26041 | B17: 粤北 | C17: 南医五院门诊 | D17: 黄梓烽 | F17: 2 | G17: 0 | H17: 11 | I17: 16 | J17: 0.45454545 | K17: 160.8 | L17: 0 | AC17: 31 | AD17: -9
A18: 26042 | B18: 粤北 | C18: 南医五院手术室 | D18: 黄梓烽 | F18: 2 | G18: 0 | H18: 19 | I18: 15 | J18: -0.21052632 | K18: 152.6 | L18: 0 | AC18: 39 | AD18: -1
A19: 26040 | B19: 粤北 | C19: 南医五院外科楼 | D19: 黄梓烽 | F19: 2 | G19: 0 | H19: 19 | I19: 14 | J19: -0.26315789 | K19: 127.8 | L19: 0 | AC19: 39 | AD19: -1
A20: 26699 | B20: 粤东 | C20: 平安服务区东区 | D20: 黄梓烽 | F20: 1 | G20: 1 | H20: 34 | I20: 51 | J20: 0.5 | K20: 802.2 | L20: 0
A21: 26395 | B21: 粤东 | C21: 平安服务区西区 | D21: 黄梓烽 | F21: 1 | G21: 1 | H21: 49 | I21: 20 | J21: -0.59183673 | K21: 292.4 | L21: 0
A22: 33412 | B22: 清远 | C22: 清远人民医院门诊 | D22: 黄梓烽 | F22: 0 | G22: 0 | H22: 35 | I22: 32 | J22: -0.085714286 | K22: 330.8 | L22: 0 | AC22: 55 | AD22: 15
A23: 33426 | B23: 清远 | C23: 清远图书馆旧馆（清远人医搬过来） | D23: 黄梓烽 | F23: 0 | G23: 0 | H23: 13 | I23: 30 | J23: 1.3076923 | K23: 290 | L23: 0 | AC23: 33 | AD23: -7
A24: 33414 | B24: 清远 | C24: 清远图书馆新馆 （清远人医搬过来） | D24: 黄梓烽 | F24: 1 | G24: 0 | H24: 32 | I24: 96 | J24: 2 | K24: 746.66 | L24: 0 | AC24: 52 | AD24: 12
A25: 66129 | B25: 粤东 | C25: 深汕服务区北区 | D25: 黄梓烽 | F25: 2 | G25: 2 | H25: 156 | I25: 65 | J25: -0.58333333 | K25: 966.4 | L25: 2
A26: 62547 | B26: 粤东 | C26: 深汕服务区南区 | D26: 黄梓烽 | F26: 2 | G26: 2 | H26: 33 | I26: 37 | J26: 0.12121212 | K26: 588.9 | L26: 0
A27: 66334 | B27: 嘉兴祥通 | C27: 水边服务区东 | D27: 黄梓烽 | F27: 2 | G27: 1 | H27: 17 | I27: 14 | J27: -0.17647059 | K27: 216.2 | L27: 0 | AC27: 37 | AD27: -3
A28: 66332 | B28: 嘉兴祥通 | C28: 水边服务区西 | D28: 黄梓烽 | F28: 1 | G28: 2 | H28: 35 | I28: 5 | J28: -0.85714286 | K28: 77 | L28: 0 | AC28: 55 | AD28: 15
A29: 33524 | B29: 顺德 | C29: 顺德宏石激光2楼 | D29: 黄梓烽 | F29: 2 | G29: 2 | H29: 32 | I29: 31 | J29: -0.03125 | K29: 203.5 | L29: 3 | AC29: 52 | AD29: 12
A30: 33425 | B30: 享当当 | C30: 享当当荔城服务区东区 | D30: 黄梓烽 | F30: 0 | G30: 0 | H30: #N/A | I30: #N/A | J30: #N/A | K30: #N/A | L30: #N/A | AC30: #N/A | AD30: #N/A
A31: 33419 | B31: 享当当 | C31: 享当当荔城服务区西区 | D31: 黄梓烽 | F31: 0 | G31: 0 | H31: #N/A | I31: #N/A | J31: #N/A | K31: #N/A | L31: #N/A | AC31: #N/A | AD31: #N/A
A32: 22340 | B32: 元山 | C32: 元山服务区东 | D32: 黄梓烽 | F32: 1 | G32: 0 | H32: 47 | I32: 35 | J32: -0.25531915 | K32: 502.4 | L32: 2 | AC32: 67 | AD32: 27
A33: 22335 | B33: 元山 | C33: 元山服务区西 | D33: 黄梓烽 | F33: 2 | G33: 2 | H33: 48 | I33: 9 | J33: -0.8125 | K33: 124.9 | L33: 1 | AC33: 68 | AD33: 28
A34: 33511 | B34: 粤北 | C34: 粤北花城服务区 | D34: 黄梓烽 | F34: 1 | G34: 2 | H34: 2 | I34: 20 | J34: 9 | K34: 285.8 | L34: 1 | AC34: 22 | AD34: -18
A35: 18857 | B35: 粤北 | C35: 粤北乐昌服务区北 | D35: 黄梓烽 | F35: 2 | G35: 2 | H35: 6 | I35: 1 | J35: -0.83333333 | K35: 16.8 | L35: 0 | AC35: 26 | AD35: -14
A36: 33413 | B36: 粤北 | C36: 粤北乐昌服务区南 | D36: 黄梓烽 | F36: 2 | G36: 2 | H36: 87 | I36: 19 | J36: -0.7816092 | K36: 286.4 | L36: 0 | AC36: 107 | AD36: 67
A37: 33416 | B37: 粤北 | C37: 粤北梅花北服务区北 | D37: 黄梓烽 | F37: 2 | G37: 3 | H37: 9 | I37: 4 | J37: -0.55555556 | K37: 60.2 | L37: 1 | AC37: 29 | AD37: -11
A38: 33418 | B38: 粤北 | C38: 粤北梅花北服务区南 | D38: 黄梓烽 | F38: 2 | G38: 2 | H38: 29 | I38: 14 | J38: -0.51724138 | K38: 201.3 | L38: 1 | AC38: 49 | AD38: 9
A39: 33512 | B39: 粤北 | C39: 粤北英德服务区北 | D39: 黄梓烽 | F39: 2 | G39: 2 | H39: 17 | I39: 15 | J39: -0.11764706 | K39: 219.1 | L39: 0 | AC39: 37 | AD39: -3
A40: 33430 | B40: 粤北 | C40: 粤北英德服务区南 | D40: 黄梓烽 | F40: 2 | G40: 2 | H40: 40 | I40: 16 | J40: -0.6 | K40: 223.1 | L40: 1 | AC40: 60 | AD40: 20
...

Sheet 小兰
A1: 机器编号 | B1: 线路 | C1: 点位名称 | D1: 所属督导 | E1: 运维人 | F1: 上周运维频率（次） | G1: 本周运维频率（次） | H1: 上周期总杯数 | I1: 本周期总杯数 | J1: 差异% | K1: 总金额 | L1: 测试杯 | M1: 停机时长 | N1: 停机原因备注 | O1: 投诉总量 | P1: 投诉率 | Q1: 缺料故障情况 | R1: 客户投诉 | S1: 异常事件 | T1: 事件备注
A2: 23401 | B2: 市区 | C2: 三江交警 | D2: 李小兰 | F2: 0 | G2: 1 | H2: 3 | I2: 0 | J2: -1 | K2: 0 | L2: 1 | AC2: 23 | AD2: -17
A3: 161673 | B3: 市区 | C3: 广东海信园区宿舍楼 | D3: 李小兰 | F3: 0 | G3: 0 | H3: 1 | I3: 4 | J3: 3 | K3: 22 | L3: 3
A4: 19662 | B4: 市区 | C4: 江门市新会中医院2号楼大堂 | D4: 李小兰 | F4: 2 | G4: 1 | H4: 22 | I4: 5 | J4: -0.77272727 | K4: 30.4 | L4: 3 | M4: 坏机，4.17已修复 | AC4: 42 | AD4: 2
A5: 13441 | B5: 市区 | C5: 江门市购书中心 | D5: 李小兰 | F5: 1 | G5: 1 | H5: 12 | I5: 5 | J5: -0.58333333 | K5: 54 | L5: 1 | AC5: 32 | AD5: -8
A6: 22254 | B6: 市区 | C6: 江门市办案中心 | D6: 李小兰 | F6: 1 | G6: 1 | H6: 10 | I6: 5 | J6: -0.5 | K6: 28 | L6: 1 | AC6: 30 | AD6: -10
A7: 13444 | B7: 市区 | C7: 江门市行政总汇4楼 | D7: 李小兰 | F7: 1 | G7: 1 | H7: 19 | I7: 6 | J7: -0.68421053 | K7: 59 | L7: 0 | M7: 无法修复.换机 | AC7: 39 | AD7: -1
A8: 22253 | B8: 市区 | C8: 鹤山中国电信 | D8: 李小兰 | F8: 2 | G8: 2 | H8: 10 | I8: 6 | J8: -0.4 | K8: 25.3 | L8: 0 | AC8: 30 | AD8: -10
A9: 26396 | B9: 市区 | C9: 北郊电信 | D9: 李小兰 | F9: 1 | G9: 1 | H9: 4 | I9: 7 | J9: 0.75 | K9: 31.6 | L9: 4 | AC9: 24 | AD9: -16
A10: 12268 | B10: 市区 | C10: 江门戴爱莲 | D10: 李小兰 | F10: 1 | G10: 1 | H10: 15 | I10: 8 | J10: -0.46666667 | K10: 64.6 | L10: 1 | AC10: 35 | AD10: -5
A11: 19823 | B11: 市区 | C11: 拘留所 | D11: 李小兰 | F11: 1 | G11: 1 | H11: 10 | I11: 11 | J11: 0.1 | K11: 50 | L11: 2 | AC11: 30 | AD11: -10
A12: 53614 | B12: 市区 | C12: 江门市芯美轩康城店 | D12: 李小兰 | F12: 1 | G12: 0 | H12: 8 | I12: 16 | J12: 1 | K12: 60.3 | L12: 0
A13: 58986 | B13: 市区 | C13: 江门市中心医院外科五楼餐厅 | D13: 李小兰 | F13: 2 | G13: 2 | H13: 21 | I13: 20 | J13: -0.047619048 | K13: 156.85 | L13: 2
A14: 12239 | B14: 市区 | C14: 江门市看守所 | D14: 李小兰 | F14: 1 | G14: 1 | H14: 38 | I14: 21 | J14: -0.44736842 | K14: 164.8 | L14: 4 | AC14: 58 | AD14: 18
A15: 33525 | B15: 市区 | C15: 江门市蓬江交警 | D15: 李小兰 | F15: 2 | G15: 2 | H15: 18 | I15: 22 | J15: 0.22222222 | K15: 66.5 | L15: 1 | AC15: 38 | AD15: -2
A16: 68721 | B16: 市区 | C16: 新会人民医院门诊 | D16: 李小兰 | F16: 1 | G16: 3 | H16: 33 | I16: 24 | J16: -0.27272727 | K16: 273.3 | L16: 4 | AC16: 53 | AD16: 13
A17: 26397 | B17: 市区 | C17: 江门市爱尔新院 | D17: 李小兰 | F17: 1 | G17: 1 | H17: 26 | I17: 27 | J17: 0.038461538 | K17: 263 | L17: 3
A18: 12248 | B18: 市区 | C18: 江门市中心医院外科4楼手术室 | D18: 李小兰 | F18: 2 | G18: 2 | H18: 25 | I18: 28 | J18: 0.12 | K18: 279.8 | L18: 2 | AC18: 45 | AD18: 5
A19: 20904 | B19: 市区 | C19: 江门中国联通 | D19: 李小兰 | F19: 1 | G19: 1 | H19: 20 | I19: 28 | J19: 0.4 | K19: 124.85 | L19: 2
A20: 163631 | B20: 市区 | C20: 广东海信园区日益便利店 | D20: 李小兰 | F20: 0 | G20: 0 | H20: 18 | I20: 31 | J20: 0.72222222 | K20: 168 | L20: 0
A21: 52935 | B21: 市区 | C21: 江门市中心医院门诊4楼 | D21: 李小兰 | F21: 2 | G21: 2 | H21: 49 | I21: 33 | J21: -0.32653061 | K21: 323.9 | L21: 2 | AC21: 69 | AD21: 29
A22: 100103 | B22: 市区 | C22: 广东海信 | D22: 李小兰 | F22: 0 | G22: 0 | H22: 13 | I22: 33 | J22: 1.5384615 | K22: 166 | L22: 0
A23: 68720 | B23: 市区 | C23: 新会人民医院住院部大堂 | D23: 李小兰 | F23: 2 | G23: 2 | H23: 30 | I23: 34 | J23: 0.13333333 | K23: 376.4 | L23: 2 | AC23: 50 | AD23: 10
A24: 23399 | B24: 市区 | C24: 江门市新会爱尔新希望 | D24: 李小兰 | F24: 2 | G24: 2 | H24: 41 | I24: 40 | J24: -0.024390244 | K24: 408 | L24: 2 | AC24: 61 | AD24: 21
A25: 18890 | B25: 市区 | C25: 江门市中心内科 | D25: 李小兰 | F25: 3 | G25: 3 | H25: 63 | I25: 57 | J25: -0.095238095 | K25: 565.64 | L25: 1 | AC25: 83 | AD25: 43
A26: 23400 | B26: 市区 | C26: 江门市松下饭堂 | D26: 李小兰 | F26: 1 | G26: 1 | H26: 49 | I26: 57 | J26: 0.16326531 | K26: 356 | L26: 8 | AC26: 69 | AD26: 29
A27: 26698 | B27: 市区 | C27: 广东阿麦斯员工之家 | D27: 李小兰 | F27: 2 | G27: 3 | H27: 49 | I27: 60 | J27: 0.2244898 | K27: 476 | L27: 2
A28: 12266 | B28: 市区 | C28: 江门供电局 | D28: 李小兰 | F28: 2 | G28: 2 | H28: 70 | I28: 79 | J28: 0.12857143 | K28: 281.05 | L28: 1 | AC28: 90 | AD28: 50
A29: 26394 | B29: 市区 | C29: 蓬江电信 | D29: 李小兰 | F29: 2 | G29: 2 | H29: 91 | I29: 81 | J29: -0.10989011 | K29: 357.6 | L29: 5 | AC29: 111 | AD29: 71
A30: 35948 | B30: 市区 | C30: 江门市中心医院外科 | D30: 李小兰 | F30: 4 | G30: 3 | H30: 96 | I30: 83 | J30: -0.13541667 | K30: 922.5 | L30: 2 | AC30: 116 | AD30: 76
A31: 16690 | B31: 市区 | C31: 江门市图书馆 | D31: 李小兰 | F31: 3 | G31: 2 | H31: 45 | I31: 97 | J31: 1.1555556 | K31: 463.5 | L31: 1 | AC31: 65 | AD31: 25
A32: 51776 | B32: 市区 | C32: 江门市中心医院门诊大堂 | D32: 李小兰 | F32: 5 | G32: 4 | H32: 343 | I32: 408 | J32: 0.18950437 | K32: 4694.74 | L32: 3 | AC32: 363 | AD32: 323
A33: 19712 | B33: 市区 | C33: 江门市第二人民医院门诊楼 | D33: 李小兰 | F33: 0 | G33: 0 | H33: #N/A | I33: #N/A | J33: #N/A | K33: #N/A | L33: #N/A | AC33: #N/A | AD33: #N/A
A34: 22520 | B34: 市区 | C34: 江门市爱尔新希望8楼 | D34: 李小兰 | F34: 0 | G34: 0 | H34: #N/A | I34: #N/A | J34: #N/A | K34: #N/A | L34: #N/A | AC34: #N/A | AD34: #N/A
A35: 21634 | B35: 市区 | C35: 江门市行政总汇3楼 | D35: 李小兰 | F35: 0 | G35: 0 | H35: #N/A | I35: #N/A | J35: #N/A | K35: #N/A | L35: #N/A | AC35: #N/A | AD35: #N/A
A36: 19391 | B36: 市区 | C36: 江门市中国移动通信信息楼 | D36: 李小兰 | F36: 0 | G36: 0 | H36: #N/A | I36: #N/A | J36: #N/A | K36: #N/A | L36: #N/A | AC36: #N/A | AD36: #N/A
B37: 健怡远程 | C37: 白云站 | D37: 李小兰 | G37: 2
B38: 健怡远程 | C38: 雅瑶站 | D38: 李小兰 | G38: 2
B39: 健怡远程 | C39: 优宝科技园 | D39: 李小兰 | G39: 2
B40: 健怡远程 | C40: 台山新宁站 | D40: 李小兰 | G40: 2

Sheet 报数
A1: 督导 | B1: 机台数 | C1: 做表机台数 | D1: 做表数 | E1: 交表率 | F1: 机均交表数 | G1: 上周交表率 | H1: 本周杯量 | I1: 上周杯量 | J1: 涨跌
A2: 初哥哥 | B2: 56 | C2: 49 | D2: 82 | E2: =C2/B2 -> 0.875 | F2: =D2/B2 -> 1.4642857 | G2: 0.77 | H2: 1775 | I2: 2959 | J2: =(H2/I2)-1 -> -0.40013518
A3: 王梓烽 | B3: 68 | C3: 52 | D3: 101 | E3: =C3/B3 -> 0.76470588 | F3: =D3/B3 -> 1.4852941 | G3: 0.72 | H3: 1899 | I3: 2499 | J3: =(H3/I3)-1 -> -0.24009604
A4: 李小兰 | B4: 28 | C4: 28 | D4: 49 | E4: =C4/B4 -> 1 | F4: =D4/B4 -> 1.75 | G4: 1 | H4: 1336 | I4: 1252 | J4: =(H4/I4)-1 -> 0.067092652

Sheet 故障
A1: 46129 | B1: 臻盈咖啡运维-粤西张礼初(臻盈咖啡-张礼初) | C1: 粤北梅花北服务区 | D1: 北区 | E1: 缺豆 | F1: 故障无影响 | H1: 46129.358 | I1: 46129.358 | J1: 0 | K1: 通驿 | M1: JL500 | N1: 技诺后台监控 | O1: 郭金燕
A2: 46128 | B2: 李小兰 | C2: 江门市行政总汇 | E2: 故障料盒电机，搅拌电机故障 | F2: 已联系兼职，待处理 | G2: 无法修复 | H2: 46128.556 | J2: -1107085.3 | K2: 市区 | M2: JL500 | N2: 技诺后台监控 | O2: 郭金燕
A3: 46125 | B3: 臻盈咖啡运维-粤西张礼初(臻盈咖啡-张礼初) | C3: 清远人民医院 | D3: 门诊 | E3: 废水桶满 | F3: 已联系兼职，待处理 | H3: 46125.364 | J3: -1107008.7 | K3: 清远 | M3: JL500 | N3: 技诺后台监控 | O3: 郭金燕

Sheet 碧桂园
A1: 碧桂园兼职交表情况（每台每周不低于2次维护）
A2: 序号 | B2: 点位 | C2: 运维人员 | D2: 负责点位 | E2: 设备台数 | F2: 4.13-4.19 | G2: 上周达标率 | H2: 上周故障明细 | I2: 4.6-4.12 | J2: 本周达标率 | K2: 本周故障明细 | L2: 督导人员
A3: 1 | B3: 粤东 | C3: 张海亮 | D3: 粤东金灶服务区 | E3: 2 | F3: 1 | G3: -3 | H3: 金灶北缺水 | I3: 1 | J3: -2 | K3: 4.7北区缺豆4.12缺豆 | L3: 王梓烽
A4: 2 | C4: 林广圳 | D4: 粤东吉隆服务区 | E4: 2 | F4: 4 | G4: ☑️ | I4: 4 | J4: ☑️ | K4: 4.6缺水 | L4: 王梓烽
A5: 3 | C5: 林海平 | D5: 粤东陶河服务区 | E5: 2 | F5: 4 | G5: ☑️ | I5: 4 | J5: ☑️ | K5: 4.6北缺水.4.12缺水 | L5: 王梓烽
A6: 4 | C6: 罗国祥 | D6: 粤东莲花山服务区 | E6: 2 | F6: 4 | G6: ☑️ | I6: 4 | J6: ☑️ | L6: 王梓烽
A7: 5 | B7: 珠三角 | C7: 龚中卫 | D7: 蚬岗服务区 | E7: 2 | F7: 3 | G7: -1 | H7: 蚬岗南缺豆 | I7: 4 | J7: ☑️ | K7: 北缺水。4.9北缺水缺豆（9.00-17.39分） | L7: 张礼初
A8: 6 | C8: 梁启光 | D8: 龙口服务区 | E8: 2 | F8: 4 | G8: ☑️ | H8: 北区缺豆 | I8: 4 | J8: ☑️ | L8: 张礼初
A9: 7 | C9: 李伟 | D9: 斗门服务区 | E9: 2 | F9: 4 | G9: ☑️ | I9: 2 | J9: -2 | L9: 张礼初
A10: 8 | C10: 余 | D10: 南沙服务区 | E10: 2 | F10: 2 | G10: ☑️ | I10: 4 | J10: ☑️ | L10: 王梓烽
A11: 9 | C11: 周年欢 | D11: 址山服务区 | E11: 1 | F11: 1 | G11: ☑️ | I11: 2 | J11: ☑️ | K11: 4.10缺水 | L11: 张礼初
A12: 10 | C12: 黎迪 | D12: 小榄服务区 | E12: 2 | F12: 2 | G12: -2 | I12: 4 | J12: ☑️ | L12: 张礼初
